<?xml version="1.0"?>
<robot name="my_robot">


<material name="blue">
	<color rgba="0 0 0.8 1"/>
</material>
<material name="black">
	<color rgba="0 0 0 1"/>
</material>
<material name="white">
	<color rgba="1 1 1 1"/>
</material>

<link name="base_link">
	<visual>
		<geometry>
			<box size="0.18 0.1 0.07"/>
		</geometry>
	</visual>
	<collision>
		<geometry>
			<box size="0.18 0.1 0.07"/>
		</geometry>
	</collision>
	<inertial>
    	<mass value="10"/>
    	<inertia ixx="1.0" ixy="0.0" ixz="0.0" iyy="1.0" iyz="0.0" izz="1.0"/>
	</inertial>	
</link>

<link name="right_front_wheel">
    <visual>
      	<origin rpy="1.57075 0 0" xyz="0 0 0"/>
      	<geometry>
        	<cylinder length="0.02" radius="0.025"/>
      	</geometry>
      	<material name="black"/>
    </visual>
    <collision>
      	<origin rpy="1.57075 0 0" xyz="0 0 0"/>
      	<geometry>
        	<cylinder length="0.02" radius="0.025"/>
    	</geometry>
    </collision>
    <inertial>
    	<mass value="1"/>
    	<inertia ixx="1.0" ixy="0.0" ixz="0.0" iyy="1.0" iyz="0.0" izz="1.0"/>
    </inertial>
</link>

<joint name="right_front_wheel_joint" type="continuous">
    <axis rpy="0 0 0" xyz="0 1 0"/>
    <parent link="base_link"/>
    <child link="right_front_wheel"/>
    <origin rpy="0 0 0" xyz="0.05 0.06 -0.02"/>
</joint>

<link name="right_back_wheel">
    <visual>
      	<origin rpy="1.57075 0 0" xyz="0 0 0"/>
      	<geometry>
        	<cylinder length="0.02" radius="0.025"/>
      	</geometry>
      	<material name="black"/>
    </visual>
    <collision>
      	<origin rpy="1.57075 0 0" xyz="0 0 0"/>
      	<geometry>
        	<cylinder length="0.02" radius="0.025"/>
    	</geometry>
    </collision>
    <inertial>
    	<mass value="1"/>
    	<inertia ixx="1.0" ixy="0.0" ixz="0.0" iyy="1.0" iyz="0.0" izz="1.0"/>
    </inertial>
</link>

<joint name="right_back_wheel_joint" type="continuous">
    <axis rpy="0 0 0" xyz="0 1 0"/>
    <parent link="base_link"/>
    <child link="right_back_wheel"/>
   <origin rpy="0 0 0" xyz="-0.05 0.06 -0.02"/>
</joint>

<link name="left_front_wheel">
    <visual>
      	<origin rpy="1.57075 0 0" xyz="0 0 0"/>
      	<geometry>
        	<cylinder length="0.02" radius="0.025"/>
      	</geometry>
      	<material name="black"/>
    </visual>
    <collision>
      	<origin rpy="1.57075 0 0" xyz="0 0 0"/>
      	<geometry>
        	<cylinder length="0.02" radius="0.025"/>
    	</geometry>
    </collision>
    <inertial>
    	<mass value="1"/>
    	<inertia ixx="1.0" ixy="0.0" ixz="0.0" iyy="1.0" iyz="0.0" izz="1.0"/>
    </inertial>
</link>

<joint name="left_front_wheel_joint" type="continuous">
    <axis rpy="0 0 0" xyz="0 1 0"/>
    <parent link="base_link"/>
    <child link="left_front_wheel"/>
   <origin rpy="0 0 0" xyz="0.05 -0.06 -0.02"/>
</joint>

<link name="left_back_wheel">
    <visual>
      	<origin rpy="1.57075 0 0" xyz="0 0 0"/>
      	<geometry>
        	<cylinder length="0.02" radius="0.025"/>
      	</geometry>
      	<material name="black"/>
    </visual>
    <collision>
      	<origin rpy="1.57075 0 0" xyz="0 0 0"/>
      	<geometry>
        	<cylinder length="0.02" radius="0.025"/>
    	</geometry>
    </collision>
    <inertial>
    	<mass value="1"/>
    	<inertia ixx="1.0" ixy="0.0" ixz="0.0" iyy="1.0" iyz="0.0" izz="1.0"/>
    </inertial>
</link>

<joint name="left_back_wheel_joint" type="continuous">
    <axis rpy="0 0 0" xyz="0 1 0"/>
    <parent link="base_link"/>
    <child link="left_back_wheel"/>
    <origin rpy="0 0 0" xyz="-0.05 -0.06 -0.02"/>
</joint>

</robot>